Workbook

Sheet Data
A1: Asset_ID | B1: Brand Type | C1: Content_Type | D1: Parent_ID | E1: Draft URL/Link | F1: Published URL/Link | G1: Author | H1: Syndication platform | I1: Headline | J1: Week # | K1: Week Of | L1: Creation Date Month | M1: Pub Date Month | N1: Created Date | O1: Publication Date | P1: Vertical | Q1: Word Count | R1: Primary Keywords | S1: Meta Description | T1: Personas (Target Audience) | U1: Draft Doc | V1: Peer Reviewer | W1: UPDATE? | X1: Test category? Yes | Y1: Reuters photo Use? Yes | Z1: Reuters Link Used? Yes | AA1: story_id | AB1: total_pvs | AC1: search_pvs | AD1: social_pvs | AE1: direct_pvs | AF1: applenews_pvs | AG1: smartnews_pvs | AH1: newsbreak_pvs | AI1: subscriber_pvs | AJ1: cluster_id | AK1: cluster_total_pvs | AL1: article_vs_co.median | AM1: cluster_vs_co.median | AN1: cluster_avg_sim_desc | AO1: topic
A2: LS-P-002 | B2: Life & Style | C2: Parent-P | E2: https://www.lifeandstylemag.com/wp-admin/post.php?post=736061&action=edit | F2: https://www.lifeandstylemag.com/posts/singles-inferno-couples-who-stayed-together-after-the-show/ | G2: Hanna Wickes | I2: ‘Single’s Inferno’: Which Couples Are Still Together From the Reality Dating Show | J2: =VLOOKUP(K2,'Weeks 2026'!A:B,2,false) -> 5 | K2: 46054 | L2: =TEXT(N2,"mmmm") -> January | M2: =TEXT(O2,"mmmm") -> February | N2: 46051 | O2: 46055 | P2: Discover | Q2: 1143 | R2: single's inferno, dating, reality show | S2: From Season 1 to Season 4, we break down what really happened to every ‘Single’s Inferno’ couple — and why none of them lasted | T2: Netflix Viewers, K-pop fans | U2: https://docs.google.com/document/d/1-l0n2VXtfqeEmmeDl1p8rdDOAkkJIEjMHG__qsNFwXs/edit?tab=t.0 | V2: Sara V | AB2: 20436 | AC2: 18750 | AD2: 19 | AE2: 1518 | AF2: 0 | AG2: 0 | AH2: 0 | AI2: 36 | AJ2: LS-P-002 | AK2: 20436 | AO2: Reality TV
A3: LS-P-006-MMC-C02 | B3: Mod Moms Club | C3: Child-C | D3: LS-P-006 | E3: https://modmomsclubstg.wpenginepowered.com/wp-admin/post.php?post=337048&action=edit | F3: https://modmomsclubstg.wpenginepowered.com/wp-admin/post.php?post=337048&action=edit | G3: Hanna Wickes | I3: Love on the Beach, Heartbreak in Reality: Why No ‘Single’s Inferno’ Couple Has Survived | J3: =VLOOKUP(K3,'Weeks 2026'!A:B,2,false) -> 5 | K3: 46054 | L3: =TEXT(N3,"mmmm") -> February | M3: =TEXT(O3,"mmmm") -> February | N3: 46055 | O3: 46055 | P3: Discover | Q3: 1024 | R3: single's inferno, dating, reality show | S3: After four seasons of Netflix’s ‘Single’s Inferno,’ no couple is still together. Here’s why every relationship ended after the cameras stopped rolling. | T3: Netflix Viewers, genral audience | U3: https://docs.google.com/document/d/1-l0n2VXtfqeEmmeDl1p8rdDOAkkJIEjMHG__qsNFwXs/edit?tab=t.0 | V3: Sara V
A4: LS-P-008 | B4: Life & Style | C4: Parent-P | E4: https://www.lifeandstylemag.com/wp-admin/post.php?post=736139&action=edit | F4: https://www.lifeandstylemag.com/posts/bindi-irwins-daughter-has-the-sweetest-bond-with-a-baby-echidna/ | G4: Hanna Wickes | I4: Bindi Sue Irwin Shares Adorable Video of Her Daughter and the Newest Member of the Australian Zoo | J4: =VLOOKUP(K4,'Weeks 2026'!A:B,2,false) -> 5 | K4: 46054 | L4: =TEXT(N4,"mmmm") -> February | M4: =TEXT(O4,"mmmm") -> February | N4: 46055 | O4: 46055 | P4: Discover | Q4: 681 | R4: bindi irwin, daughter, zoo | S4: Bindi Irwin shared a heart-melting video of her daughter Grace bonding with a baby echidna at Australia Zoo — and fans can’t get enough. | T4: General Audience | U4: https://docs.google.com/document/d/1w8GKIGqfty9-xPc0yHEp_au_PtGAS8u8dGVawzeBrmQ/edit?usp=sharing | V4: Ryan B | AB4: 287 | AC4: 61 | AD4: 10 | AE4: 175 | AF4: 0 | AG4: 0 | AH4: 0 | AI4: 3 | AJ4: LS-P-008 | AK4: 287 | AO4: Pets
A5: LS-P-008-MMC-C02 | B5: Mod Moms Club | C5: Child-C | D5: LS-P-008 | E5: https://modmomsclubstg.wpenginepowered.com/wp-admin/post.php?post=337038&action=edit | F5: https://modmomsclubstg.wpenginepowered.com/parenting/bindi-irwins-daughter-is-friends-with-echidna/ | G5: Hanna Wickes | I5: Bindi Irwin’s Daughter Is Best Friends With an Echidna — This Video Will Make Every ’90s Kid Smile | J5: =VLOOKUP(K5,'Weeks 2026'!A:B,2,false) -> 5 | K5: 46054 | L5: =TEXT(N5,"mmmm") -> February | M5: =TEXT(O5,"mmmm") -> February | N5: 46055 | O5: 46055 | P5: Discover | Q5: 829 | R5: bindi irwin, daughter, zoo | S5: If you grew up watching Steve Irwin, this sweet video of Bindi Irwin’s daughter and an echidna will hit you right in the feels. | T5: Early 2000s Nostalgia | U5: https://docs.google.com/document/d/1w8GKIGqfty9-xPc0yHEp_au_PtGAS8u8dGVawzeBrmQ/edit?usp=sharing | V5: Ryan B
A6: MMC-P-010 | B6: Mod Moms Club | C6: Parent-P | E6: https://modmomsclubstg.wpenginepowered.com/wp-admin/post.php?post=337001&action=edit | F6: https://modmomsclub.com/lifestyle-entertainment/celebrity/khaby-lame-new-deal-ai-digital-twin/ | G6: Ryan Brennan | I6: Khaby Lame’s $975 Million Deal Signals a New Era: When Your Digital Twin Becomes the Product | L6: =TEXT(N6,"mmmm") -> January | N6: 46050 | P6: Discover | Q6: 842 | R6: khaby lame, khaby lame deal, rich sparkle | S6: Khaby Lame sold his company in a $975 million deal that licenses his face and voice for AI. Here’s what his AI digital twin means for the creator economy. | T6: Aspiring Content Creator/Side Hustler | U6: https://docs.google.com/document/d/1upYTG3nqmQNb5xeIHAG60DvSNC9h0DmGfqz2SQTo87A/edit?usp=sharing | AJ6: MMC-P-010 | AK6: 532
A7: MMC-P-010-LS-C02 | B7: Life & Style | C7: Child-C | D7: MMC-P-010 | E7: https://www.lifeandstylemag.com/wp-admin/post.php?post=736114&action=edit | F7: https://www.lifeandstylemag.com/posts/khaby-lame-sells-company-authorizes-use-of-ai-digital-twin/ | G7: Ryan Brennan | I7: From Factory Worker to $975 Million: How Khaby Lame Built a Social Media Empire You Can Learn From | L7: =TEXT(N7,"mmmm") -> January | N7: 46050 | P7: Discover | Q7: 1134 | R7: khaby lame, khaby lame deal, rich sparkle | S7: Khaby Lame sold his company in a $975 million deal that licenses his face and voice for AI. Here’s what his AI digital twin means for the creator economy. | T7: Tech-Curious Professional/AI Watcher | U7: https://docs.google.com/document/d/1upYTG3nqmQNb5xeIHAG60DvSNC9h0DmGfqz2SQTo87A/edit?usp=sharing | AB7: 532 | AC7: 293 | AD7: 9 | AE7: 210 | AF7: 0 | AG7: 0 | AH7: 0 | AI7: 0 | AO7: Business
A8: MMC-P-012 | B8: Mod Moms Club | C8: Parent-P | E8: https://modmomsclubstg.wpenginepowered.com/wp-admin/post.php?post=337004&action=edit | F8: https://modmomsclub.com/lifestyle-entertainment/celebrity/selma-blair-ms-diagnosis-update-return-acting/ | G8: Ryan Brennan | I8: Selma Blair’s Return to Acting Offers a Masterclass in Redefining What’s Possible After Chronic Illness | L8: =TEXT(N8,"mmmm") -> January | N8: 46051 | P8: Discover | Q8: 898 | R8: selma blair, selma blair ms, multiple sclerosis | S8: Selma Blair opens up about being relapse-free from multiple sclerosis (MS) and shares hope amid her return to acting after thinking her career was finished. | T8: Pop Culture Nostalgic | U8: https://docs.google.com/document/d/1CGpHMESQJ47oruN2KknlA1cy0KBcdpH8grEcMj7YGbI/edit?usp=sharing | AJ8: MMC-P-012
A9: MMC-P-012-LS-C02 | B9: Life & Style | C9: Child-C | D9: MMC-P-012 | E9: https://www.lifeandstylemag.com/wp-admin/post.php?post=736118&action=edit | F9: https://www.lifeandstylemag.com/posts/selma-blair-details-return-to-acting-after-thinking-career-was-done/ | G9: Ryan Brennan | I9: Selma Blair Is Back: Beloved ’90s Star Returns to Acting After Thinking She’d Never Work Again | L9: =TEXT(N9,"mmmm") -> January | N9: 46051 | P9: Discover | Q9: 1096 | R9: selma blair, selma blair ms, multiple sclerosis | S9: Selma Blair opens up about being relapse-free from multiple sclerosis (MS) and shares hope amid her return to acting after thinking her career was finished. | T9: Trend Hunter B2C | U9: https://docs.google.com/document/d/1CGpHMESQJ47oruN2KknlA1cy0KBcdpH8grEcMj7YGbI/edit?usp=sharing
A10: MMC-P-014 | B10: Mod Moms Club | C10: Parent-P | E10: https://modmomsclubstg.wpenginepowered.com/wp-admin/post.php?post=337007&action=edit | F10: https://modmomsclub.com/lifestyle-entertainment/celebrity/jessie-james-decker-scary-nashville-ice-storm/ | G10: Ryan Brennan | I10: Jessie James Decker’s Backyard Turns Dangerous Amid Nashville’s Record-Breaking Ice Storm | L10: =TEXT(N10,"mmmm") -> January | N10: 46051 | P10: Discover | Q10: 1221 | R10: jessie james decker, exploding trees, nashville ice storm | S10: Nashville’s ice storm has gone viral with "exploding trees," widespread power outages and celebrities like Jessie James Decker sharing footage of the damage. | T10: General Audience | U10: https://docs.google.com/document/d/1Lhss9qyZCKsWvEbmgPRx47-25pxOJa4ZFYeSqESpQXU/edit?tab=t.0 | V10: Sara V | AJ10: MMC-P-014 | AK10: 259
A11: MMC-P-014-LS-C02 | B11: Life & Style | C11: Child-C | D11: MMC-P-014 | E11: https://www.lifeandstylemag.com/wp-admin/post.php?post=736123&action=edit | F11: https://www.lifeandstylemag.com/posts/jessie-james-decker-shares-video-of-exploding-trees-amid-ice-storm/ | G11: Ryan Brennan | I11: Jessie James Decker’s Terrifying Ice Storm Video Has Nashville Celebrities Sharing Their Own Footage | L11: =TEXT(N11,"mmmm") -> January | N11: 46051 | P11: Discover | Q11: 1217 | R11: jessie james decker, exploding trees, nashville ice storm | S11: Nashville’s ice storm has gone viral with "exploding trees," widespread power outages and celebrities like Jessie James Decker sharing footage of the damage. | T11: Trend Hunter B2C | U11: https://docs.google.com/document/d/1Lhss9qyZCKsWvEbmgPRx47-25pxOJa4ZFYeSqESpQXU/edit?tab=t.0 | V11: Sara V | AB11: 259 | AC11: 116 | AD11: 10 | AE11: 83 | AF11: 0 | AG11: 0 | AH11: 0 | AI11: 3 | AO11: Weather
A12: MMC-P-016 | B12: Mod Moms Club | C12: Parent-P | E12: https://modmomsclubstg.wpenginepowered.com/wp-admin/post.php?post=337016&action=edit | F12: https://modmomsclub.com/lifestyle-entertainment/celebrity/jenna-bush-hager-declassifies-secret-service-alias/ | G12: Ryan Brennan | I12: Jenna Bush Hager Reveals the Secret Identity She Used as a Teenager in the White House | L12: =TEXT(N12,"mmmm") -> January | N12: 46052 | P12: Discover | Q12: 662 | R12: jenna bush hager, secret service code names, holly crawford | S12: Jenna Bush Hager reveals the fake name the Secret Service gave her as an 18-year-old — and it turns out she wasn’t the only one running around with that name! | T12: Morning Show Enthusiast | U12: https://docs.google.com/document/d/1q_vx0VWhpoIj1rHTcX8wSlt3XvrOcB994dxHfat4P4A/edit?tab=t.0 | V12: Sara V | AJ12: MMC-P-016 | AK12: 263
A13: MMC-P-016-LS-C02 | B13: Life & Style | C13: Child-C | D13: MMC-P-016 | E13: https://www.lifeandstylemag.com/wp-admin/post.php?post=736079&action=edit | F13: https://www.lifeandstylemag.com/posts/title-page-sep-sitename-jenna-bush-hagers-secret-service-name-was-very-on-brand/ | G13: Ryan Brennan | I13: Remember When Jenna Bush Hager Finally Revealed Her Secret Service Alias — Fans Still Can’t Get Enough | L13: =TEXT(N13,"mmmm") -> January | N13: 46052 | P13: Discover | Q13: 699 | R13: jenna bush hager, secret service code names, holly crawford | S13: Jenna Bush Hager reveals the fake name the Secret Service gave her as an 18-year-old — and it turns out she wasn’t the only one running around with that name! | T13: General Audience | U13: https://docs.google.com/document/d/1q_vx0VWhpoIj1rHTcX8wSlt3XvrOcB994dxHfat4P4A/edit?tab=t.0 | V13: Sara V | AB13: 263 | AC13: 73 | AD13: 39 | AE13: 119 | AF13: 0 | AG13: 0 | AH13: 0 | AI13: 2 | AO13: Celebrity Families
A14: MMC-P-018 | B14: Mod Moms Club | C14: Parent-P | E14: https://modmomsclubstg.wpenginepowered.com/wp-admin/post.php?post=337022&action=edit | F14: https://modmomsclub.com/lifestyle-entertainment/celebrity/pete-davidson-vhs-collection-rich/ | G14: Ryan Brennan | I14: Pete Davidson’s Billion-Dollar Idea Is the Most Relatable Millennial Collector Fail Ever | L14: =TEXT(N14,"mmmm") -> January | N14: 46052 | P14: Discover | Q14: 564 | R14: pete davidson, vhs tapes, vhs collection | S14: Pete Davidson finally shares the fate of his collection of 10,000 sealed VHS tapes — and the nostalgia-fueled gamble was nowhere close to paying off. | T14: Nostalgic Millennial Collector | U14: https://docs.google.com/document/d/1aD0AklCcuoIzLIofcU0dF_JhDTDii7LBrP9FcEoOdNM/edit?tab=t.0 | V14: Sara V | AJ14: MMC-P-018 | AK14: 153
A15: MMC-P-018-LS-C02 | B15: Life & Style | C15: Child-C | D15: MMC-P-018 | E15: https://www.lifeandstylemag.com/wp-admin/post.php?post=736095&action=edit | F15: https://www.lifeandstylemag.com/posts/title-page-sep-sitename-pete-davidsons-vhs-collection-has-entered-its-flop-era/ | G15: Ryan Brennan | I15: Pete Davidson’s Billion-Dollar VHS Gamble: The Hilarious Update Fans Have Been Waiting For | L15: =TEXT(N15,"mmmm") -> January | N15: 46052 | P15: Discover | Q15: 710 | R15: pete davidson, vhs tapes, vhs collection | S15: Pete Davidson finally shares the fate of his collection of 10,000 sealed VHS tapes — and the nostalgia-fueled gamble was nowhere close to paying off. | T15: Pop Culture Enthusiast | U15: https://docs.google.com/document/d/1aD0AklCcuoIzLIofcU0dF_JhDTDii7LBrP9FcEoOdNM/edit?tab=t.0 | V15: Sara V | AB15: 153 | AC15: 34 | AD15: 14 | AE15: 89 | AF15: 0 | AG15: 0 | AH15: 0 | AI15: 0 | AO15: Television
A16: MMC-P-020 | B16: Mod Moms Club | C16: Parent-P | E16: https://modmomsclubstg.wpenginepowered.com/wp-admin/post.php?post=337027&action=edit | F16: https://modmomsclub.com/lifestyle-entertainment/celebrity/ava-raine-stepping-away-wwe-nxt/ | G16: Ryan Brennan | I16: ‘The Rock’s Daughter Ava Raine Says She’s Stepping Away From WWE & NXT | L16: =TEXT(N16,"mmmm") -> January | N16: 46052 | P16: Discover | Q16: 703 | R16: ava raine, simone johnson, dwayne johnson daughter, the rock daughter | S16: Ava Raine, daughter of Dwayne “The Rock” Johnson, is leaving the WWE at 24 and walking away from a historic family legacy to begin a new chapter of her life. | T16: Pop Culture-Following Parent | U16: https://docs.google.com/document/d/1qSLLwTXDpI7x_-oYuMmXgOH3uDNQo8STxhOUdjULtvw/edit?usp=sharing | V16: Sara V | AJ16: MMC-P-020 | AK16: 620
A17: MMC-P-020-LS-C02 | B17: Life & Style | C17: Child-C | D17: MMC-P-020 | E17: https://www.lifeandstylemag.com/wp-admin/post.php?post=736106&action=edit | F17: https://www.lifeandstylemag.com/posts/ava-raine-announces-surprise-exit-from-wwe-and-nxt/ | G17: Ryan Brennan | I17: Dwayne Johnson’s Daughter Departs NXT After Historic Run as WWE’s Youngest General Manager | L17: =TEXT(N17,"mmmm") -> January | N17: 46052 | P17: Discover | Q17: 641 | R17: ava raine, simone johnson, dwayne johnson daughter, the rock daughter | S17: Dwayne Johnson’s daughter, Ava Raine, says she's leaving NXT after making history as WWE’s youngest General Manager. | T17: Wrestling Fan & Sports Entertainment Enthusiast | U17: https://docs.google.com/document/d/1qSLLwTXDpI7x_-oYuMmXgOH3uDNQo8STxhOUdjULtvw/edit?usp=sharing | V17: Sara V | AB17: 620 | AC17: 382 | AD17: 17 | AE17: 180 | AF17: 0 | AG17: 0 | AH17: 0 | AI17: 1 | AO17: Sports
A18: LS-P-022 | B18: Life & Style | C18: Parent-P | E18: https://www.lifeandstylemag.com/?p=736143&preview=true | F18: https://www.lifeandstylemag.com/posts/essentials-to-pack-for-a-flight-that-feels-first-class/ | G18: Lauren Schuster | I18: Skip the Upgrade Fee: How to Create Your Own First-Class Experience for the Price of Economy | J18: =VLOOKUP(K18,'Weeks 2026'!A:B,2,false) -> 5 | K18: 46054 | L18: =TEXT(N18,"mmmm") -> February | M18: =TEXT(O18,"mmmm") -> February | N18: 46055 | O18: 46055 | P18: Experiences | Q18: 904 | R18: travel, flights, Vacation, | S18: Upgrade your travel experience with carry-on essentials that bring comfort, style, and first-class vibes to every flight, no upgrade required | T18: Budget-Conscious Frequent Traveler | U18: https://docs.google.com/document/d/1MwM6muzt1RXKmI4CpjT05uBhBhp_LLS8Dd8SXjI79kM/edit?tab=t.0 | V18: Lauren JG | AB18: 78 | AC18: 10 | AD18: 9 | AE18: 50 | AF18: 0 | AG18: 0 | AH18: 0 | AI18: 0 | AJ18: LS-P-022 | AK18: 78
A19: LS-P-022-MMC-C02 | B19: Mod Moms Club | C19: Child-C | D19: LS-P-022 | E19: https://modmomsclubstg.wpenginepowered.com/wp-admin/post.php?post=337049&action=edit | F19: https://modmomsclub.com/lifestyle-entertainment/your-calm-flight-checklist-simple-carry-on-essentials-that-help-anxious-flyers-feel-in-control/ | G19: Lauren Schuster | I19: Your Calm-Flight Checklist: Simple Carry-On Essentials That Help Anxious Flyers Feel in Control | J19: =VLOOKUP(K19,'Weeks 2026'!A:B,2,false) -> 5 | K19: 46054 | L19: =TEXT(N19,"mmmm") -> February | M19: =TEXT(O19,"mmmm") -> February | N19: 46055 | O19: 46055 | P19: Experiences | Q19: 1105 | R19: airplane, flight, travel, traveling | S19: Ease flight anxiety with luxurious carry-on essentials designed for comfort and calm, so every trip feels more relaxed from takeoff to landing | T19: First-Time or Anxious Flyer | U19: https://docs.google.com/document/d/1MwM6muzt1RXKmI4CpjT05uBhBhp_LLS8Dd8SXjI79kM/edit?tab=t.0 | V19: Lauren JG
A20: LS-P-024 | B20: Life & Style | C20: Parent-P | E20: https://www.lifeandstylemag.com/wp-admin/post.php?post=736100&action=edit | F20: https://www.lifeandstylemag.com/posts/how-to-plan-your-spring-garden-this-winter/ | G20: Lauren J-G | I20: Here’s How to Plan Your Spring Garden This Winter Without the Overwhelm | J20: =VLOOKUP(K20,'Weeks 2026'!A:B,2,false) -> 5 | K20: 46054 | L20: =TEXT(N20,"mmmm") -> February | M20: =TEXT(O20,"mmmm") -> February | N20: 46055 | O20: 46055 | P20: Everyday Life | Q20: 1596 | R20: gardening, home, lifestyle, planning garden | S20: Don't wait to start working on your garden in the winter months. Here's a step-by-step guide to help you have a blooming garden come spring | T20: Trend Hunter | U20: https://docs.google.com/document/d/1qslDaR69eW929cyYIWoyQjBc_OjEXyWwy3-vAJT_dDQ/edit?tab=t.0 | V20: Lauren S | AB20: 121 | AC20: 3 | AD20: 3 | AE20: 103 | AF20: 0 | AG20: 0 | AH20: 0 | AI20: 0 | AJ20: LS-P-024 | AK20: 121 | AO20: Home & Garden
A21: LS-P-024-MMC-C02 | B21: Mod Moms Club | C21: Child-C | D21: LS-P-024 | E21: https://modmomsclubstg.wpenginepowered.com/wp-admin/post.php?post=337026&action=edit | F21: https://modmomsclubstg.wpenginepowered.com/parenting/your-familys-winter-guide-to-planning-a-spring-garden-together/ | G21: Lauren J-G | I21: Your Family’s Winter Guide to Planning a Spring Garden Together | J21: =VLOOKUP(K21,'Weeks 2026'!A:B,2,false) -> 5 | K21: 46054 | L21: =TEXT(N21,"mmmm") -> February | M21: =TEXT(O21,"mmmm") -> February | N21: 46055 | O21: 46055 | P21: Everyday Life | Q21: 1293 | R21: garden, spring gardening, winter gardening, home tips | S21: Plan your winter garden as a family and set the stage for a thriving spring. Easy tips to prep, dream, and grow together. | T21: Overwhelmed Working Parent | U21: https://docs.google.com/document/d/1qslDaR69eW929cyYIWoyQjBc_OjEXyWwy3-vAJT_dDQ/edit?tab=t.0 | V21: Lauren S
A22: LS-P-026 | B22: Life & Style | C22: Parent-P | E22: https://www.lifeandstylemag.com/wp-admin/post.php?post=736085&action=edit | F22: https://www.lifeandstylemag.com/posts/your-ultimate-guide-for-spring-cleaning/ | G22: Lauren J-G | I22: Your No-Stress Spring Cleaning Playbook: A Room-by-Room Guide to a Fresher Home | J22: =VLOOKUP(K22,'Weeks 2026'!A:B,2,false) -> 5 | K22: 46054 | L22: =TEXT(N22,"mmmm") -> February | M22: =TEXT(O22,"mmmm") -> February | N22: 46055 | O22: 46055 | P22: Everyday Life | Q22: 1104 | R22: cleaning, cleaning hacks, home, lifestyle, spring cleaning | S22: Spring is almost here, which means it's time to get ready to refresh our homes after winter. Here's the ultimate guide for spring cleaning | T22: Trend Hunter | U22: https://docs.google.com/document/d/16znh8k3LtycwIYGUuRLb6B1kvk4IX-3smOKfUTLbVm0/edit?tab=t.0 | V22: Lauren S | AB22: 138 | AC22: 27 | AD22: 4 | AE22: 91 | AF22: 0 | AG22: 0 | AH22: 0 | AI22: 1 | AJ22: LS-P-026 | AK22: 138 | AO22: Home Improvement
A23: LS-P-026-MMC-C02 | B23: Mod Moms Club | C23: Child-C | D23: LS-P-026 | E23: https://modmomsclubstg.wpenginepowered.com/wp-admin/post.php?post=337020&action=edit | F23: https://modmomsclubstg.wpenginepowered.com/parenting/spring-cleaning-made-simple-a-busy-parents-guide-to-a-healthier-home-without-losing-your-weekend/ | G23: Lauren J-G | I23: Spring Cleaning Made Simple: A Busy Parent’s Guide to a Healthier Home Without Losing Your Weekend | J23: =VLOOKUP(K23,'Weeks 2026'!A:B,2,false) -> 5 | K23: 46054 | L23: =TEXT(N23,"mmmm") -> February | M23: =TEXT(O23,"mmmm") -> February | N23: 46055 | O23: 46056 | P23: Everyday Life | Q23: 1151 | R23: spring cleaning, home tips, cleaning with kids | S23: Overwhelmed by spring cleaning with kids? This step-by-step guide helps parents declutter, organize, and refresh their home without the stress. | T23: Overwhelmed Working Parent | U23: https://docs.google.com/document/d/16znh8k3LtycwIYGUuRLb6B1kvk4IX-3smOKfUTLbVm0/edit?tab=t.0 | V23: Lauren S
A24: LS-P-028 | B24: Life & Style | C24: Parent-P | E24: https://www.lifeandstylemag.com/wp-admin/post.php?post=736146&action=edit | F24: https://www.lifeandstylemag.com/posts/what-is-an-ebug-tiktok-creator-answers-everyones-questions/ | G24: Ryan Brennan | I24: What Is an EBUG? The NHL’s Most Unusual Role, Explained by a Fan Favorite | L24: =TEXT(N24,"mmmm") -> February | N24: 46055 | P24: Discover | Q24: 1463 | R24: emergency backup goalie, ebug, timm chiusano | T24: Casual Hockey Fan | U24: https://docs.google.com/document/d/1HqZimoVIvjs4VnnYTVlFpuL1d0WfYfpgPuv6KtrROBI/edit?usp=sharing | V24: Hanna W | AB24: 115 | AC24: 39 | AD24: 6 | AE24: 56 | AF24: 0 | AG24: 0 | AH24: 0 | AI24: 0 | AJ24: LS-P-028 | AK24: 115 | AO24: Sports
A25: LS-P-028-MMC-C02 | B25: Mod Moms Club | C25: Child-C | D25: LS-P-028 | E25: https://modmomsclubstg.wpenginepowered.com/wp-admin/post.php?post=337042&action=edit | F25: https://modmomsclub.com/lifestyle-entertainment/celebrity/what-is-an-ebug-emergency-backup-goalie/ | G25: Ryan Brennan | I25: What Every Hockey Parent Should Know About the NHL’s Emergency Backup Goalie Role | L25: =TEXT(N25,"mmmm") -> February | N25: 46055 | P25: Discover | Q25: 1255 | R25: emergency backup goalie, ebug, timm chiusano | U25: https://docs.google.com/document/d/1HqZimoVIvjs4VnnYTVlFpuL1d0WfYfpgPuv6KtrROBI/edit?usp=sharing | V25: Hanna W
A26: LS-P-030 | B26: Life & Style | C26: Parent-P | E26: https://www.lifeandstylemag.com/posts/alex-warrens-grammys-performance-went-wrong-heres-why/ | F26: https://www.lifeandstylemag.com/posts/alex-warrens-grammys-performance-went-wrong-heres-why/ | G26: Hanna Wickes | I26: Alex Warren’s Grammy Debut Hit a Technical Snag—Here’s How He Handled It Like a Pro | J26: =VLOOKUP(K26,'Weeks 2026'!A:B,2,false) -> 5 | K26: 46054 | L26: =TEXT(N26,"mmmm") -> February | M26: =TEXT(O26,"mmmm") -> February | N26: 46055 | O26: 46055 | P26: Discover | Q26: 716 | R26: alex warren, grammys, music, celebrity news | S26: Alex Warren experienced every performer’s nightmare when his in-ear monitors malfunctioned during the 2026 Grammys. | T26: General Audience | U26: https://docs.google.com/document/d/1BJs2J2Kw7AMmTUDhGjgKxMeqbS5rjTIVDHIe64MwCTU/edit?tab=t.0 | V26: Ryan B | AB26: 1040 | AC26: 857 | AD26: 8 | AE26: 149 | AF26: 0 | AG26: 0 | AH26: 0 | AI26: 7 | AJ26: LS-P-030 | AK26: 1040 | AO26: Events and Attractions
A27: LS-P-030-MMC-C02 | B27: Mod Moms Club | C27: Child-C | D27: LS-P-030 | E27: https://modmomsclubstg.wpenginepowered.com/lifestyle-entertainment/celebrity/alex-warrens-grammy-debut/ | F27: https://modmomsclub.com/lifestyle-entertainment/celebrity/alex-warrens-grammy-debut/ | G27: Hanna Wickes | I27: Alex Warren’s Grammys Debut Hit a Snag—But His Wife Kouvr’s Response Is the Real Story | J27: =VLOOKUP(K27,'Weeks 2026'!A:B,2,false) -> 5 | K27: 46054 | L27: =TEXT(N27,"mmmm") -> February | M27: =TEXT(O27,"mmmm") -> February | N27: 46055 | O27: 46055 | P27: Discover | Q27: 802 | R27: alex warren, grammys, music, celebrity news | S27: Alex Warren’s Grammy performance didn’t go as planned—but his response, and his wife’s support, won over fans and parents alike. | T27: Millennial Parent Following Pop Culture | U27: https://docs.google.com/document/d/1BJs2J2Kw7AMmTUDhGjgKxMeqbS5rjTIVDHIe64MwCTU/edit?tab=t.0 | V27: Ryan B
A28: LS-P-032 | B28: Life & Style | C28: Parent-P | E28: https://www.lifeandstylemag.com/wp-admin/post.php?post=736180&action=edit | F28: https://www.lifeandstylemag.com/posts/the-hidden-tribute-inside-kelsea-ballerinis-grammy-gown/ | G28: Ryan Brennan | I28: Kelsea Ballerini’s Grammy Gown Held a Heartbreaking Tribute That Fans Couldn’t See | J28: =VLOOKUP(K28,'Weeks 2026'!A:B,2,false) -> 5 | K28: 46054 | L28: =TEXT(N28,"mmmm") -> February | M28: =TEXT(O28,"mmmm") -> February | N28: 46055.594 | O28: 46055.594 | P28: Discover | Q28: 1042 | R28: kelsea ballerini, kelsea ballerini grammy | S28: Fans missed a powerful detail in Kelsea Ballerini’s Grammy gown—a hidden tribute honoring her late dog Dibs stitched close to her heart. | T28: Country Music Fan & Concert-Goer | U28: https://docs.google.com/document/d/16oks1xPwhSexKC8RplhoJH-vFami3dqnr_9NouWok3g/edit?tab=t.0 | V28: Hanna W | AB28: 308 | AC28: 127 | AD28: 10 | AE28: 110 | AF28: 0 | AG28: 0 | AH28: 0 | AI28: 0 | AJ28: LS-P-032 | AK28: 308 | AO28: Country Music
A29: LS-P-032-MMC-C02 | B29: Mod Moms Club | C29: Child-C | D29: LS-P-032 | E29: https://modmomsclubstg.wpenginepowered.com/wp-admin/post.php?post=337059&action=edit | F29: https://modmomsclub.com/lifestyle-entertainment/celebrity/kelsea-ballerini-grammy-dress-dog-tribute/ | G29: Ryan Brennan | I29: Kelsea Ballerini’s Hidden Grammy Dress Tribute Honors the ‘Greatest Gift’ of Her Life | J29: =VLOOKUP(K29,'Weeks 2026'!A:B,2,false) -> 5 | K29: 46054 | L29: =TEXT(N29,"mmmm") -> February | M29: =TEXT(O29,"mmmm") -> February | N29: 46055.594 | O29: 46055.594 | P29: Discover | Q29: 1057 | R29: kelsea ballerini, kelsea ballerini grammy | S29: Kelsea Ballerini’s Grammy dress held a secret tribute to her late dog Dibs, honoring the “greatest gift” of her life on one of music's biggest nights. | T29: Pet Owner Experiencing or Anticipating Loss | U29: https://docs.google.com/document/d/16oks1xPwhSexKC8RplhoJH-vFami3dqnr_9NouWok3g/edit?tab=t.0 | V29: Hanna W
A30: LS-P-034 | B30: Life & Style | C30: Parent-P | E30: https://modmomsclubstg.wpenginepowered.com/wp-admin/post.php?post=337105&action=edit | F30: https://www.lifeandstylemag.com/posts/cant-miss-italian-restaurants-in-nyc-for-every-price-range/ | G30: Lauren Schuster | I30: The Visiting Food Tourist’s Ultimate Guide to Italian Dining in NYC: Where to Eat When Every Meal Counts | J30: =VLOOKUP(K30,'Weeks 2026'!A:B,2,false) -> 5 | K30: 46054 | L30: =TEXT(N30,"mmmm") -> February | M30: February | N30: 46055 | O30: 46057 | P30: Experiences | Q30: 1029 | R30: dining, italian, new york city, restaurants | S30: From casual pizza slices to Michelin-level fine dining, you won’t want to miss these Italian restaurant in NYC | T30: Visiting Food Tourist | U30: https://docs.google.com/document/d/1Wn047ljvzBZ01CKY9M4PwKXGB2nWSG8GBwKr5fsr-Y4/edit?tab=t.0 | V30: Lauren JG | AB30: 209 | AC30: 18 | AD30: 5 | AE30: 166 | AF30: 0 | AG30: 0 | AH30: 0 | AI30: 10 | AJ30: LS-P-034 | AK30: 209 | AO30: Food & Drink
A31: LS-P-034-MMC-C02 | B31: Mod Moms Club | C31: Child-C | D31: LS-P-034 | E31: https://www.lifeandstylemag.com/wp-admin/post.php?post=736255&action=edit | F31: https://modmomsclubstg.wpenginepowered.com/lifestyle-entertainment/food/your-ultimate-guide-to-italian-dining-in-new-york-city-cheap-eats-to-michelin-spots/ | G31: Lauren Schuster | I31: Your Ultimate Guide to Italian Dining in New York City: Cheap Eats to Michelin Stars | J31: =VLOOKUP(K31,'Weeks 2026'!A:B,2,false) -> 5 | K31: 46054 | L31: =TEXT(N31,"mmmm") -> February | M31: =TEXT(O31,"mmmm") -> February | N31: 46055 | O31: 46058 | P31: Experiences | Q31: 923 | R31: dining, italian, new york city, restaurants | S31: From casual pizza slices to Michelin-level fine dining, be sure to check out these Italian restaurants on your next trip to NYC | T31: General Audience | U31: https://docs.google.com/document/d/1Wn047ljvzBZ01CKY9M4PwKXGB2nWSG8GBwKr5fsr-Y4/edit?tab=t.0 | V31: Lauren JG
A32: MMC-P-036 | B32: Mod Moms Club | C32: Parent-P | E32: https://modmomsclubstg.wpenginepowered.com/wp-admin/post.php?post=337070&action=edit | F32: https://modmomsclubstg.wpenginepowered.com/lifestyle-entertainment/bob-ross-paintings-sold-public-broadcasting/ | G32: Ryan Brennan | I32: Bob Ross Paintings Just Sold for 8x Their Value — And the Proceeds Are Going to a Great Cause | J32: =VLOOKUP(K32,'Weeks 2026'!A:B,2,false) -> 5 | K32: 46054 | L32: =TEXT(N32,"mmmm") -> February | M32: =TEXT(O32,"mmmm") -> February | N32: 46055 | O32: 46056 | P32: Discover | Q32: 580 | R32: bob ross, bob ross paintings, the joy of painting | S32: Three Bob Ross paintings smashed auction estimates, selling for $1.2 million and highlighting how cultural nostalgia is reshaping the art market. | T32: Trend Hunter B2C | U32: https://docs.google.com/document/d/1PhjpJs-FfaOSm2eJsE1-PbiikztvCPSES6tG6JVUJd8/edit?usp=sharing | V32: Hanna W | AJ32: MMC-P-036 | AK32: 108
A33: MMC-P-036-LS-C02 | B33: Life & Style | C33: Child-C | D33: MMC-P-036 | E33: https://www.lifeandstylemag.com/wp-admin/post.php?post=736195&action=edit | F33: https://www.lifeandstylemag.com/posts/bob-ross-paintings-just-became-the-feel-good-story-of-the-year/ | G33: Ryan Brennan | I33: Three Bob Ross Paintings You Grew Up Watching Just Raised $1.2 Million for Public Broadcasting | J33: =VLOOKUP(K33,'Weeks 2026'!A:B,2,false) -> 5 | K33: 46054 | L33: =TEXT(N33,"mmmm") -> February | M33: =TEXT(O33,"mmmm") -> February | N33: 46055 | O33: 46056 | P33: Discover | Q33: 968 | R33: bob ross, bob ross paintings, the joy of painting | S33: Bob Ross paintings made on "The Joy of Painting" sold for $1.2M, nearly eight times estimates, with proceeds going back to PBS. | T33: Nostalgic Boomer Art Enthusiast | U33: https://docs.google.com/document/d/1PhjpJs-FfaOSm2eJsE1-PbiikztvCPSES6tG6JVUJd8/edit?usp=sharing | V33: Hanna W | AB33: 108 | AC33: 19 | AD33: 5 | AE33: 67 | AF33: 0 | AG33: 0 | AH33: 0 | AI33: 0 | AO33: Television
A34: LS-P-038 | B34: Life & Style | C34: Parent-P | E34: https://www.lifeandstylemag.com/wp-admin/post.php?post=736208&action=edit | F34: https://www.lifeandstylemag.com/posts/how-to-allergy-proof-your-home/ | G34: Lauren J-G | I34: Struggle With Allergies? Your Guide to Allergy Proofing Your Home | J34: =VLOOKUP(K34,'Weeks 2026'!A:B,2,false) -> 5 | K34: 46054 | L34: =TEXT(N34,"mmmm") -> February | M34: =TEXT(O34,"mmmm") -> February | N34: 46056 | O34: 46056 | P34: Everyday Life | Q34: 1352 | R34: cleaning, cleaning tips, cleaning hacks, lifestyle, home | S34: Indoor allergens like dust mites and mold can worsen allergy and asthma symptoms. Learn how to allergy-proof your home with cleaning tips | T34: General Audience | U34: https://docs.google.com/document/d/1NRWc9EIqVU_TBfLWPBRUGNBaM0mvry5MkjUQIYS745w/edit?tab=t.0 | V34: Lauren S | AB34: 69 | AC34: 12 | AD34: 7 | AE34: 43 | AF34: 0 | AG34: 0 | AH34: 0 | AI34: 0 | AJ34: LS-P-038 | AK34: 69 | AO34: Allergies
A35: LS-P-038-MMC-C02 | B35: Mod Moms Club | C35: Child-C | D35: LS-P-038 | E35: https://modmomsclubstg.wpenginepowered.com/wp-admin/post.php?post=337080&action=edit | F35: https://modmomsclubstg.wpenginepowered.com/parenting/a-parents-guide-to-allergy-proofing-your-home/ | G35: Lauren J-G | I35: A Parent’s Guide to Allergy-Proofing Your Home This Spring | J35: =VLOOKUP(K35,'Weeks 2026'!A:B,2,false) -> 5 | K35: 46054 | L35: =TEXT(N35,"mmmm") -> February | M35: =TEXT(O35,"mmmm") -> February | N35: 46056 | O35: 46056 | P35: Everyday Life | Q35: 1144 | R35: cleaning, cleaning tips, cleaning hacks, lifestyle, home | S35: Allergies or asthma acting up at home? These doctor-recommended cleaning tips help reduce dust, dander, and other indoor allergens year-round. | T35: Parent of a Child with Asthma or Allergies | U35: https://docs.google.com/document/d/1NRWc9EIqVU_TBfLWPBRUGNBaM0mvry5MkjUQIYS745w/edit?tab=t.0 | V35: Lauren S
A36: LS-P-040 | B36: Life & Style | C36: Parent-P | E36: https://www.lifeandstylemag.com/wp-admin/post.php?post=736220&action=edit | F36: https://www.lifeandstylemag.com/posts/this-dollar-tree-diy-jewelry-organizer-is-going-viral-on-tiktok/ | G36: Lauren J-G | I36: This Dollar Tree DIY Hack Is Taking Over TikTok — and It Looks Way More Expensive Than It Is | J36: =VLOOKUP(K36,'Weeks 2026'!A:B,2,false) -> 5 | K36: 46054 | L36: =TEXT(N36,"mmmm") -> February | M36: =TEXT(O36,"mmmm") -> February | N36: 46056 | O36: 46056 | P36: Everyday Life | Q36: 1020 | R36: diy hack. dollar. tree diy. home, lifestyle | S36: A Dollar Tree DIY project from a TikTok creator is going viral for turning cheap items into a stylish organizer anyone can make at home | T36: General Audience | U36: https://docs.google.com/document/d/1UUuGTqsvUARXN7b4qI9gd8K3F5Ak57w8Eu9iYhQI86c/edit?tab=t.0 | V36: Lauren S | AB36: 174 | AC36: 49 | AD36: 9 | AE36: 87 | AF36: 0 | AG36: 0 | AH36: 0 | AI36: 0 | AJ36: LS-P-040 | AK36: 174 | AO36: Home & Garden
A37: LS-P-040-MMC-C02 | B37: Mod Moms Club | C37: Child-C | D37: LS-P-040 | E37: https://modmomsclubstg.wpenginepowered.com/wp-admin/post.php?post=337093&action=edit | F37: https://modmomsclubstg.wpenginepowered.com/lifestyle-entertainment/turn-dollar-tree-finds-into-a-stunning-two-tier-tray/ | G37: Lauren J-G | I37: Turn Dollar Tree Finds Into a Stunning Two-Tier Tray | J37: =VLOOKUP(K37,'Weeks 2026'!A:B,2,false) -> 5 | K37: 46054 | L37: =TEXT(N37,"mmmm") -> February | M37: =TEXT(O37,"mmmm") -> February | N37: 46056 | O37: 46056 | P37: Everyday Life | Q37: 1045 | R37: diy hack. dollar. tree diy. home, lifestyle | S37: See this incredible Dollar Tree DIY project that is making the rounds on the internet. You can even do it yourself at home. | T37: CRAFTY EMPTY-NESTER ON FIXED INCOME | U37: https://docs.google.com/document/d/1UUuGTqsvUARXN7b4qI9gd8K3F5Ak57w8Eu9iYhQI86c/edit?tab=t.0 | V37: Lauren S
A38: LS-P-042 | B38: Life & Style | C38: Parent-P | E38: https://www.lifeandstylemag.com/wp-admin/post.php?post=736194&action=edit | F38: https://www.lifeandstylemag.com/posts/why-the-buffalo-bills-are-betting-on-the-nfls-youngest-head-coach/ | G38: Hanna Wickes | I38: Joe Brady Takes the Helm: What the Bills’ Bold Hire Means for Buffalo’s Championship Window | J38: =VLOOKUP(K38,'Weeks 2026'!A:B,2,false) -> 5 | K38: 46054 | L38: =TEXT(N38,"mmmm") -> February | M38: =TEXT(O38,"mmmm") -> February | N38: 46055 | O38: 46056 | P38: Discover | Q38: 970 | R38: buffalo bills, joe brady, head coach | S38: The Buffalo Bills have hired Joe Brady as their next head coach. Here’s why the move signals a major shift for the franchise. | T38: Trend Hunter B2C | U38: https://docs.google.com/document/d/16oks1xPwhSexKC8RplhoJH-vFami3dqnr_9NouWok3g/edit?tab=t.0 | V38: Ryan B | AB38: 309 | AC38: 223 | AD38: 1 | AE38: 75 | AF38: 0 | AG38: 0 | AH38: 0 | AI38: 1 | AJ38: LS-P-042 | AK38: 309 | AO38: Sports
A39: LS-P-042-MMC-C02 | B39: Mod Moms Club | C39: Child-C | D39: LS-P-042 | E39: https://modmomsclubstg.wpenginepowered.com/wp-admin/post.php?post=337069&action=edit | F39: https://modmomsclubstg.wpenginepowered.com/lifestyle-entertainment/meet-joe-brady-the-young-buffalo-bills-coach/ | G39: Hanna Wickes | I39: Joe Brady Named Buffalo Bills Head Coach: What to Know About the NFL’s Youngest Hire | J39: =VLOOKUP(K39,'Weeks 2026'!A:B,2,false) -> 5 | K39: 46054 | L39: =TEXT(N39,"mmmm") -> February | M39: =TEXT(O39,"mmmm") -> February | N39: 46055 | O39: 46056 | P39: Discover | Q39: 1202 | R39: buffalo bills, joe brady, head coach | S39: Joe Brady is officially the Buffalo Bills’ new head coach. Learn about his age, contract, coaching journey, and relationship with Josh Allen. | T39: General Audience | U39: https://docs.google.com/document/d/16oks1xPwhSexKC8RplhoJH-vFami3dqnr_9NouWok3g/edit?tab=t.0 | V39: Ryan B
A40: LS-P-044 | B40: Life & Style | C40: Parent-P | E40: https://www.lifeandstylemag.com/wp-admin/post.php?post=736218&action=edit | F40: https://www.lifeandstylemag.com/posts/little-miss-sunshine-cast-reflects-on-20-years-of-memories/ | G40: Ryan Brennan | I40: The Little Miss Sunshine Cast Reflects on a Movie That Made Dysfunction Feel Universal | J40: =VLOOKUP(K40,'Weeks 2026'!A:B,2,false) -> 5 | K40: 46054 | L40: =TEXT(N40,"mmmm") -> February | M40: =TEXT(O40,"mmmm") -> February | N40: 46056 | O40: 46056 | P40: Discover | Q40: 1331 | R40: little miss sunshine, little miss sunshine cast, abigail breslin | S40: Twenty years after its Sundance premiere, the Little Miss Sunshine cast reunites to honor the film’s Oscar legacy and remember Alan Arkin. | T40: Awards Season/Film Industry Follower | U40: https://docs.google.com/document/d/1IOMh178EdVVFGnoBUoZ10EcNgsQKusrT74i6IPO4jWQ/edit?usp=sharing | V40: Hanna W | AB40: 145 | AC40: 48 | AD40: 9 | AE40: 68 | AF40: 0 | AG40: 0 | AH40: 0 | AI40: 0 | AJ40: LS-P-044 | AK40: 145 | AO40: Movies
...

Sheet Trends
A1: Week # | B1: Article Hits | C1: Article Misses | D1: Article Hit Rate | E1: Cluster Hits | F1: Cluster Misses | G1: Cluster Hit Rate | H1: Target (1-in-4) | J1: Author | K1: Articles | L1: Avg Weekly Output | M1: Avg PVs | N1: Cluster Diversity | O1: Avg Sim (Desc) | P1: Avg Sim (Body 400w) | Q1: Hit Rate
A2: 6 | B2: 16 | C2: 26 | D2: 0.38095238 | E2: 9 | F2: 12 | G2: 0.42857143 | H2: 0.25 | J2: Hanna WIckes | K2: 4 | L2: 4 | M2: 17529 | N2: 3 | O2: 0.9484 | P2: 0.8653 | Q2: 0.5
A3: 7 | B3: 32 | C3: 70 | D3: 0.31372549 | E3: 17 | F3: 21 | G3: 0.44736842 | H3: 0.25 | J3: Lauren JG | K3: 2 | L3: 2 | M3: 1496 | N3: 2 | Q3: 0.5
A4: 8 | B4: 34 | C4: 88 | D4: 0.27868852 | E4: 19 | F4: 27 | G4: 0.41304348 | H4: 0.25 | J4: Ryan Brennan | K4: 620 | L4: 56.36 | M4: 4190 | N4: 203 | O4: 0.9121 | P4: 0.7267 | Q4: 0.28
A5: 9 | B5: 25 | C5: 112 | D5: 0.18248175 | E5: 11 | F5: 38 | G5: 0.2244898 | H5: 0.25 | J5: Hanna Wickes | K5: 612 | L5: 55.64 | M5: 2818 | N5: 204 | O5: 0.9293 | P5: 0.7609 | Q5: 0.2574
A6: 10 | B6: 32 | C6: 110 | D6: 0.22535211 | E6: 15 | F6: 35 | G6: 0.3 | H6: 0.25 | J6: Samantha Agate | K6: 189 | L6: 47.25 | M6: 995 | N6: 63 | O6: 0.9039 | P6: 0.7929 | Q6: 0.1528
A7: 11 | B7: 36 | C7: 77 | D7: 0.31858407 | E7: 18 | F7: 22 | G7: 0.45 | H7: 0.25 | J7: Allison Palmer | K7: 144 | L7: 18 | M7: 3134 | N7: 50 | O7: 0.9023 | P7: 0.7973 | Q7: 0.1301
A8: 12 | B8: 29 | C8: 136 | D8: 0.17575758 | E8: 21 | F8: 49 | G8: 0.3 | H8: 0.25 | J8: Lauren Schuster | K8: 133 | L8: 12.09 | M8: 649 | N8: 64 | O8: 0.9248 | P8: 0.7891 | Q8: 0.0891
A9: 13 | B9: 36 | C9: 179 | D9: 0.16744186 | E9: 20 | F9: 66 | G9: 0.23255814 | H9: 0.25 | J9: Lauren J-G | K9: 182 | L9: 16.55 | M9: 737 | N9: 70 | O9: 0.8939 | P9: 0.6737 | Q9: 0.0286
A10: 14 | B10: 34 | C10: 181 | D10: 0.15813953 | E10: 21 | F10: 57 | G10: 0.26923077 | H10: 0.25
A11: 15 | B11: 27 | C11: 142 | D11: 0.15976331 | E11: 17 | F11: 43 | G11: 0.28333333 | H11: 0.25

Sheet Ranges
A1: Properties | C1: Content_Type | E1: Content Types | G1: Type of Asset | I1: Author | K1: Smart News
A2: Us Weekly | C2: Parent-P | E2: Explainer | G2: Trend Unit | I2: Hanna Wickes | K2: MSN
A3: Us Weekly Español | C3: Child-C | E3: Everything to Know | G3: Core | I3: Ryan Brennan | K3: Apple
A4: Woman's World | G4: Bridge | I4: Lauren J-G | K4: Newsbreak
A5: Life & Style | G5: Discover | I5: Lauren Schuster | K5: Yahoo!
A6: In Touch | G6: Version | I6: Allison Palmer | K6: Google News
A7: Closer
A8: J-14
A9: Soaps in Depth
A10: First for Women
A11: OK! Magazine
A12: Mod Moms Club
A13: Miami Herald
A14: Kansas City Star
A15: Sacramento Bee
A16: Charlotte Observer
A17: Raleigh N&O
A18: Fort Worth Star-Telegram
... A34: Mirmar

Sheet By Month

Sheet By Author

Sheet By Vertical

Sheet Weeks 2026
A1: Date of week start (Sunday) | B1: Week #
A2: 46026 | B2: 1
A3: 46033 | B3: 2
A4: 46040 | B4: 3
A5: 46047 | B5: 4
A6: 46054 | B6: 5
A7: 46061 | B7: 6
A8: 46068 | B8: 7
A9: 46075 | B9: 8
A10: 46082 | B10: 9
A11: 46089 | B11: 10
A12: 46096 | B12: 11
A13: 46103 | B13: 12
... A53: 46383 | B53: 52

Sheet By Site

Sheet Pivot

Sheet Content Calendar
A1: Month | B1: Target Date | C1: Content Title/Idea | D1: Content Type | E1: Status | F1: Priority | G1: Owner | H1: Peer Reviewer | L1: Vertical | M1: Homebase | N1: Platform | O1: Campaign/Series | P1: SEO Keywords | Q1: Notes
A2: 46054 | B2: 46071 | C2: Condo or Single-Family Home | D2: Article | E2: Published | F2: High | G2: Allison | L2: Everyday Living | M2: Miami | N2: CUE | O2: Homebuyers Guide | Q2: Miami Moving Companies
A3: 46055 | B3: 46072 | C3: Condo or Single-Family Home | D3: Article | E3: Published | F3: High | G3: Allison | L3: Everyday Living | M3: Miami | N3: CUE | O3: Homebuyers Guide | Q3: Miami Security Systems
A4: 46056 | B4: 46071 | C4: KCM Homebuyers Initial Content Plan | D4: Article | E4: Published | F4: High | G4: Allison | K4: https://www.kansascity.com/news/business/home-buyers-guide/article314746910.html | L4: Everyday Living | M4: KC | N4: CUE | O4: Homebuyers Guide | Q4: KC Neighborhoods
A5: 46057 | B5: 46072 | C5: KCM Homebuyers Initial Content Plan | D5: Article | E5: Published | F5: High | G5: Allison | K5: https://www.kansascity.com/news/business/home-buyers-guide/article314749321.html | L5: Everyday Living | M5: KC | N5: CUE | O5: Homebuyers Guide | Q5: KC Condo or Single Family
A6: 46058 | B6: 46073 | C6: KCM Homebuyers Initial Content Plan | D6: Article | E6: Published | F6: High | G6: Allison | K6: https://www.kansascity.com/news/business/home-buyers-guide/article314760348.html | L6: Everyday Living | M6: KC | N6: CUE | O6: Homebuyers Guide | Q6: KC Home Inspections
A7: 46059 | B7: 46071 | C7: KCM Homebuyers Initial Content Plan | D7: Article | E7: Published | F7: High | G7: Allison | K7: https://www.kansascity.com/news/business/home-buyers-guide/article314776069.html | L7: Everyday Living | M7: KC | N7: CUE | O7: Homebuyers Guide | Q7: KC Property Taxes
A8: 46060 | B8: 46072 | C8: KCM Homebuyers Initial Content Plan | D8: Article | E8: Published | F8: High | G8: Allison | K8: https://www.kansascity.com/news/business/home-buyers-guide/article314807018.html | L8: Everyday Living | M8: KC | N8: CUE | O8: Homebuyers Guide | Q8: KC Competitive Offers
A9: 46061 | B9: 46071 | C9: World Cup Guide: Miami | D9: Article | E9: Published | F9: High | G9: Taylor (FL) | K9: https://www.miamiherald.com/sports/fifa-world-cup/article314387069.html | L9: Experiences | M9: Miami | N9: CUE | O9: FIFA | Q9: World Cup Miami: Main
A10: 46062 | B10: 46078 | C10: World Cup Guide: Miami | D10: Article | E10: In Progress | F10: Medium | G10: Taylor (FL) | J10: https://cue.gcp.misitemgr.com/cue-web/#/main?uri=https:%2F%2Fcue.gcp.misitemgr.com%2Fwebservice%2Fescenic%2Fcontent%2F314820016&mimetype=x-ece%2Fstory&extra=%7B%22package%22:%2278cca8ea-79f6-4703-9cb0-143ff11dc5d9%22%7D&name=Florida_s_Largest_Urban_Park_Offers_World_Cup_Visitors_a_Hidden_Escape_Just_Minutes_From_the_Action | K10: https://www.miamiherald.com/sports/fifa-world-cup/article314820016.html | L10: Experiences | M10: Miami | N10: CUE | O10: FIFA | Q10: World Cup Miami: Oleta River State Park
A11: 46063 | B11: 46073 | C11: World Cup Guide: Miami | D11: Article | E11: Published | F11: High | G11: Taylor (FL) | K11: https://www.miamiherald.com/sports/fifa-world-cup/article314760602.html | L11: Experiences | M11: Miami | N11: CUE | O11: FIFA | Q11: World Cup Miami: Aventura Mall
A12: 46064 | B12: 46078 | C12: World Cup Guide: Miami | D12: Article | E12: In Progress | F12: Medium | G12: Taylor (FL) | J12: https://cue.gcp.misitemgr.com/cue-web/#/main?uri=https:%2F%2Fcue.gcp.misitemgr.com%2Fwebservice%2Fescenic%2Fcontent%2F314819835&mimetype=x-ece%2Fstory&extra=%7B%22package%22:%22f7c88ff0-85bc-424f-9b6e-0883c92a21f5%22%7D&name=Gulfstream_Park_Village_Guide_Where_World_Cup_2026_Fans_Can_Keep_the_Celebration_Going | K12: https://www.miamiherald.com/sports/fifa-world-cup/article314819835.html | L12: Experiences | M12: Miami | N12: CUE | O12: FIFA | Q12: World Cup Miami: Gulfstream Park Village
A13: 46065 | B13: 46077 | C13: World Cup Guide: Miami | D13: Article | E13: In Progress | F13: Medium | G13: Taylor (FL) | K13: https://www.miamiherald.com/sports/fifa-world-cup/article314909198.html | L13: Experiences | M13: Miami | N13: CUE | O13: FIFA | Q13: World Cup Miami: Dining Options
A14: 46066 | B14: 46078 | C14: World Cup Guide: Miami | D14: Article | E14: In Progress | F14: Medium | G14: Taylor (FL) | K14: https://www.miamiherald.com/sports/fifa-world-cup/article314909347.html | L14: Experiences | M14: Miami | N14: CUE | O14: FIFA | Q14: World Cup Miami: Rolling Oaks Park
A15: 46067 | B15: 46077 | C15: World Cup Guide: Miami | D15: Article | E15: In Progress | F15: Medium | G15: Taylor (FL) | K15: https://www.miamiherald.com/sports/fifa-world-cup/article314909388.html | L15: Experiences | M15: Miami | N15: CUE | O15: FIFA | Q15: World Cup Miami: Snake Creek Trail
A16: 46068 | B16: 46078 | C16: World Cup Guide: Miami | D16: Article | E16: In Progress | F16: Medium | G16: Taylor (FL) | K16: https://www.miamiherald.com/sports/fifa-world-cup/article314909666.html | L16: Experiences | M16: Miami | N16: CUE | O16: FIFA | Q16: World Cup Miami: Calder Casino
A17: 46068 | B17: 46078 | C17: World Cup Guide: Miami | D17: Article | E17: In Progress | F17: Medium | G17: Taylor (FL) | K17: https://www.miamiherald.com/sports/fifa-world-cup/article314909729.html | L17: Experiences | M17: Miami | N17: CUE | O17: FIFA | Q17: World Cup Miami: Miami Beach
A18: 46069 | B18: 46079 | C18: World Cup Guide: Kansas City | D18: Article | E18: In Progress | F18: Medium | G18: Taylor (FL) | L18: Experiences | M18: KC | N18: CUE | O18: FIFA | Q18: World Cup KC: Mainbar
A19: 46070 | B19: 46079 | C19: World Cup Guide: Kansas City | D19: Article | E19: In Progress | F19: Medium | G19: Taylor (FL) | L19: Experiences | M19: KC | N19: CUE | O19: FIFA | Q19: World Cup KC: FIFA Fest
A20: 46071 | B20: 46078 | C20: World Cup Guide: Kansas City | D20: Article | E20: In Progress | F20: Medium | G20: Taylor (FL) | L20: Experiences | M20: KC | N20: CUE | O20: FIFA | Q20: World Cup KC: Truman Sports Complex
A21: 46072 | B21: 46079 | C21: World Cup Guide: Kansas City | D21: Article | E21: In Progress | F21: Medium | G21: Taylor (FL) | L21: Experiences | M21: KC | N21: CUE | O21: FIFA | Q21: World Cup KC: 18th Vine District
A22: 46073 | B22: 46079 | C22: World Cup Guide: Kansas City | D22: Article | E22: In Progress | F22: Medium | G22: Taylor (FL) | L22: Experiences | M22: KC | N22: CUE | O22: FIFA | Q22: World Cup KC: Zoo
A23: 46074 | B23: 46079 | C23: World Cup Guide: Kansas City | D23: Article | E23: In Progress | F23: Medium | G23: Taylor (FL) | L23: Experiences | M23: KC | N23: CUE | O23: FIFA | Q23: World Cup KC: Boulevard
A24: 46075 | B24: 46080 | C24: World Cup Guide: Kansas City | D24: Article | E24: In Progress | F24: Medium | G24: Taylor (FL) | L24: Experiences | M24: KC | N24: CUE | O24: FIFA | Q24: World Cup KC: Crown Center
A25: 46076 | B25: 46080 | C25: World Cup Guide: Kansas City | D25: Article | E25: In Progress | F25: Medium | G25: Taylor (FL) | L25: Experiences | M25: KC | N25: CUE | O25: FIFA | Q25: World Cup KC: Plaza
A26: 46077 | B26: 46080 | C26: World Cup Guide: Kansas City | D26: Article | E26: In Progress | F26: Medium | G26: Taylor (FL) | L26: Experiences | M26: KC | N26: CUE | O26: FIFA | Q26: World Cup KC: Nelson Atkins
A27: 46078 | B27: 46080 | C27: World Cup Guide: Kansas City | D27: Article | E27: In Progress | F27: Medium | G27: Taylor (FL) | L27: Experiences | M27: KC | N27: CUE | O27: FIFA | Q27: World Cup KC: Worlds of Fun
A28: 46079 | B28: 46079 | C28: World Cup Guide: Kansas City | D28: Article | E28: In Progress | F28: Medium | G28: Taylor (FL) | L28: Experiences | M28: KC | N28: CUE | O28: FIFA | Q28: World Cup KC: Barbecue
A29: 46080 | B29: 46079 | C29: World Cup Guide: Fort Worth | D29: Article | E29: In Progress | F29: Medium | G29: Taylor (FL) | L29: Experiences | M29: FTW | N29: CUE | O29: FIFA | Q29: World Cup FTW: Main
... A42: 46088 | B42: 46090 | C42: World Cup Guide: Bay Area | D42: Article | E42: Approved | F42: Medium | G42: Allison | L42: Experiences | M42: SAC | N42: CUE | O42: FIFA | Q42: World Cup Bay Area: Family Attractions
A43: 46081 | B43: 46080 | C43: What Happens to Your Portfolio If Markets Drop 30% at Retirement? | D43: Article | E43: In Progress | F43: High | N43: CUE
A44: 46081 | B44: 46080 | C44: How to Build an Income Floor That Lasts 30 Years | D44: Article | E44: Published | F44: High | G44: Lauran J-G | H44: SV | I44: https://cue.gcp.misitemgr.com/cue-web/#/main?escenicid=314820042&extra=%7B%22package%22:%22ece-auto-gen-c52c6585-3f62-42e4-b48a-9a64fb1f202c%22%7D&filter=%7B%22searchCriteria%22:%7B%22name%22:%22%22,%22searchTerm%22:%22%22,%22contentType%22:%22%2Fwebservice%2Fescenic%2Fpublication%2Fbnd%2Fmodel%2Fcontent-type%2Fstoryline%22,%22labels%22:%7B%22%2Fwebservice%2Fescenic%2Fpublication%2Fbnd%2Fmodel%2Fcontent-type%2Fstoryline%22:%7B%22title%22:%22Story%22%7D,%22org_unit:8a8f26f5-63f5-11f0-ae19-959fd20885e0%22:%7B%22title%22:%22KansasCity%22%7D,%22%2Fwebservice%2Fescenic%2Fcontent%2Fstate%2Fpublished%22:%7B%22title%22:%22Published%22%7D,%22creationdate%22:%22In%20the%20last%20year%22%7D,%22createdAt%22:%222026-02-24T17:45:40.473Z%22,%22dateRange%22:%7B%22creationdate%22:%7B%22start%22:%222025-02-24T07:00:00Z%22,%22end%22:%222027-02-25T07:00:00Z%22%7D%7D,%22daysBefore%22:%7B%22creationdate%22:%22365%22%7D,%22facetSummary%22:%22Document%20Type:%20Story,%20Time-span%20(creationdate):%20In%20the%20last%20year,%20States:%20Published%22,%22priority%22:-1,%22panelName%22:%22Search%22,%22presentation%22:%22%22,%22sorting%22:%22%22,%22customFilters%22:%5B%5D,%22customFacetStrings%22:%7B%7D,%22state%22:%22%2Fwebservice%2Fescenic%2Fcontent%2Fstate%2Fpublished%22,%22orgUnit%22:%22org_unit:8a8f26f5-63f5-11f0-ae19-959fd20885e0%22%7D%7D | K44: https://www.miamiherald.com/living/article314820042.html | L44: Everyday Living | M44: MIA | N44: CUE | O44: API | P44: retirement income floor, guaranteed income retirement | Q44: Educational | R44: Pillar content. Embed white paper Braze card.
A45: 46081 | B45: 46080 | C45: Is It Too Late to Refinance? What Pre-Retirees Need to Know in 2026 | D45: Article | E45: Published | F45: High | G45: Lauran J-G | H45: CP | I45: https://cue.gcp.misitemgr.com/cue-web/#/main?escenicid=314821467&extra=%7B%22package%22:%22ece-auto-gen-47a3210a-4e56-4c1e-a5fc-5fcb022d51f1%22%7D&filter=%7B%22searchCriteria%22:%7B%22name%22:%22%22,%22searchTerm%22:%22%22,%22labels%22:%7B%22org_unit:8a8f26f5-63f5-11f0-ae19-959fd20885e0%22:%7B%22title%22:%22KansasCity%22%7D,%22creationdate%22:%22In%20the%20last%20year%22%7D,%22createdAt%22:%222026-02-24T18:47:47.404Z%22,%22dateRange%22:%7B%22creationdate%22:%7B%22start%22:%222025-02-24T07:00:00Z%22,%22end%22:%222027-02-25T07:00:00Z%22%7D%7D,%22daysBefore%22:%7B%22creationdate%22:%22365%22%7D,%22facetSummary%22:%22Time-span%20(creationdate):%20In%20the%20last%20year%22,%22priority%22:-1,%22panelName%22:%22Search%22,%22presentation%22:%22%22,%22sorting%22:%22%22,%22customFilters%22:%5B%5D,%22customFacetStrings%22:%7B%7D,%22orgUnit%22:%22org_unit:8a8f26f5-63f5-11f0-ae19-959fd20885e0%22%7D%7D | K45: https://www.miamiherald.com/living/article314821467.html | L45: Everyday Living | M45: MIA | N45: CUE | O45: API | P45: refinancing a house 2026, mortgage refinance pre-retirement | Q45: Decision-Trigger | R45: Timely + evergreen. Surfaces complexity → WP conversion.
A46: 46081 | B46: 46080 | C46: Roth Conversion Strategy: A Step-by-Step Guide for Ages 55–65 | D46: Article | E46: In Progress | F46: High | L46: Everyday Living | M46: MIA | N46: CUE
A47: 46081 | B47: 46080 | C47: The Inflation Risk Most Retirees Are Ignoring | D47: Article | E47: In Progress | F47: High | G47: Lauran J-G | H47: SV | I47: https://cue.gcp.misitemgr.com/cue-web/#/main?escenicid=314823045&extra=%7B%22package%22:%22ece-auto-gen-3a9cbd0f-3685-408c-80e3-2fe256852605%22%7D&filter=%7B%22searchCriteria%22:%7B%22name%22:%22%22,%22searchTerm%22:%22money%22,%22labels%22:%7B%22creationdate%22:%22In%20the%20last%20year%22%7D,%22createdAt%22:%222026-02-24T20:07:02.325Z%22,%22dateRange%22:%7B%22creationdate%22:%7B%22start%22:%222025-02-24T07:00:00Z%22,%22end%22:%222027-02-25T07:00:00Z%22%7D%7D,%22daysBefore%22:%7B%22creationdate%22:%22365%22%7D,%22facetSummary%22:%22Time-span%20(creationdate):%20In%20the%20last%20year%22,%22priority%22:-1,%22panelName%22:%22Search%22,%22presentation%22:%22%22,%22sorting%22:%22%22,%22customFilters%22:%5B%5D,%22customFacetStrings%22:%7B%7D%7D%7D | K47: https://www.miamiherald.com/living/article314823045.html | L47: Everyday Living | M47: MIA | N47: CUE | O47: API | P47: inflation retirement risk, TIPS bonds retirement | Q47: Educational | R47: Pillar content. Pairs with Roth Conversion article for nurture sequence.
A48: 46081 | B48: 46080 | C48: How Much Does Your 401(k) Factor Into Your Mortgage Qualification? | D48: Article | E48: In Progress | F48: High | L48: Everyday Living | M48: MIA | N48: CUE
A49: 46081 | B49: 46080 | C49: HSA Pitfalls That Could Cost You in Retirement | D49: Article | E49: In Progress | F49: High | G49: Lauren S | H49: SV (has CTA) | I49: https://cue.gcp.misitemgr.com/cue-web/#/main?escenicid=314840223&extra=%7B%22package%22:%22ece-auto-gen-52b0740e-cacd-4c31-999f-4c9d3df5bc16%22%7D&filter=%7B%22searchCriteria%22:%7B%22name%22:%22%22,%22searchTerm%22:%22retire%22,%22contentType%22:%22%2Fwebservice%2Fescenic%2Fpublication%2Fbnd%2Fmodel%2Fcontent-type%2Fstoryline%22,%22labels%22:%7B%22%2Fwebservice%2Fescenic%2Fpublication%2Fbnd%2Fmodel%2Fcontent-type%2Fstoryline%22:%7B%22title%22:%22Story%22%7D,%22%2Fwebservice%2Fescenic%2Fcontent%2Fstate%2Fpublished%22:%7B%22title%22:%22Published%22%7D,%22org_unit:8acc2ff9-63f5-11f0-ae19-959fd20885e0%22:%7B%22title%22:%22Miami%22%7D,%22creationdate%22:%22In%20the%20last%20year%22%7D,%22createdAt%22:%222026-02-25T21:27:58.454Z%22,%22dateRange%22:%7B%22creationdate%22:%7B%22start%22:%222025-02-25T05:00:00Z%22,%22end%22:%222027-02-26T05:00:00Z%22%7D%7D,%22daysBefore%22:%7B%22creationdate%22:%22365%22%7D,%22facetSummary%22:%22Document%20Type:%20Story,%20Time-span%20(creationdate):%20In%20the%20last%20year,%20States:%20Published%22,%22priority%22:-1,%22panelName%22:%22Search%22,%22presentation%22:%22%22,%22sorting%22:%22%22,%22customFilters%22:%5B%5D,%22customFacetStrings%22:%7B%7D,%22state%22:%22%2Fwebservice%2Fescenic%2Fcontent%2Fstate%2Fpublished%22,%22orgUnit%22:%22org_unit:8acc2ff9-63f5-11f0-ae19-959fd20885e0%22%7D%7D | K49: https://www.miamiherald.com/living/article314824437.html | L49: Everyday Living | M49: MIA | N49: CUE | O49: API | P49: HSA mistakes, health savings account retirement pitfalls | Q49: Decision-Trigger | R49: High search volume. Emotional hook. Surfaces WP as solution.
A50: 46081 | B50: 46080 | C50: The Triple Tax Advantage: How to Maximize Your HSA Before Retirement | D50: Article | E50: In Progress | F50: High | L50: Everyday Living | M50: MIA | N50: CUE
A51: 46081 | B51: 46080 | C51: 2025 401(k) Contribution Limit Increase: What It Means for Your Retirement Timeline | D51: Article | E51: In Progress | F51: High | L51: Everyday Living | M51: MIA | N51: CUE
A52: 46081 | B52: 46080 | C52: How to Choose the Best Financial Planner for Pre-Retirement | D52: Article | E52: Published | F52: High | G52: Lauren S | H52: SV (has CTA) | I52: https://cue.gcp.misitemgr.com/cue-web/#/main?escenicid=314835931&extra=%7B%22package%22:%22ece-auto-gen-22c16a41-010f-4e80-a72a-32f8fa36e3a3%22%7D&filter=%7B%22searchCriteria%22:%7B%22name%22:%22%22,%22searchTerm%22:%22%22,%22contentType%22:%22%2Fwebservice%2Fescenic%2Fpublication%2Fbnd%2Fmodel%2Fcontent-type%2Fstoryline%22,%22labels%22:%7B%22%2Fwebservice%2Fescenic%2Fpublication%2Fbnd%2Fmodel%2Fcontent-type%2Fstoryline%22:%7B%22title%22:%22Story%22%7D,%22%2Fwebservice%2Fescenic%2Fcontent%2Fstate%2Fpublished%22:%7B%22title%22:%22Published%22%7D,%22org_unit:8acc2ff9-63f5-11f0-ae19-959fd20885e0%22:%7B%22title%22:%22Miami%22%7D,%22%2Fwebservice%2Fescenic%2Fsection%2F102662%22:%7B%22pathInfo%22:%22mia-tab%22,%22title%22:%22Business%22%7D,%22creationdate%22:%22In%20the%20last%20year%22%7D,%22createdAt%22:%222026-02-25T19:29:49.051Z%22,%22dateRange%22:%7B%22creationdate%22:%7B%22start%22:%222025-02-25T05:00:00Z%22,%22end%22:%222027-02-26T05:00:00Z%22%7D%7D,%22daysBefore%22:%7B%22creationdate%22:%22365%22%7D,%22facetSummary%22:%22Document%20Type:%20Story,%20Time-span%20(creationdate):%20In%20the%20last%20year,%20States:%20Published,%20Sections:%20Business%22,%22priority%22:-1,%22panelName%22:%22Search%22,%22presentation%22:%22%22,%22sorting%22:%22%22,%22customFilters%22:%5B%5D,%22customFacetStrings%22:%7B%7D,%22state%22:%22%2Fwebservice%2Fescenic%2Fcontent%2Fstate%2Fpublished%22,%22sections%22:%22%2Fwebservice%2Fescenic%2Fsection%2F102662%22,%22orgUnit%22:%22org_unit:8acc2ff9-63f5-11f0-ae19-959fd20885e0%22%7D%7D | J52: https://www.womansworld.com/life/money/how-to-find-the-right-financial-planner-when-retirement-is-around-the-corner | K52: https://www.miamiherald.com/living/article314835931.html | L52: Everyday Living | M52: MIA/WW | N52: CUE | O52: API | P52: best financial planners for retirement, how to choose financial advisor | Q52: Educational | R52: High commercial intent. Fisher Investments brand alignment opportunity.
...

Sheet Creature Features
A1: Creature Feature Pitches

Sheet APPLE REWRITE CALENDAR
A1: Date | B1: Day of Week | C1: Week | D1: Article 1 - Title | E1: Article 1 - Source | F1: Article 1 - Original Views | G1: Article 1 - Published | H1: Article 1 - Rewrite Score | I1: Article 2 - Title | J1: Article 2 - Source | K1: Article 2 - Original Views | L1: Article 2 - Published | M1: Article 2 - Rewrite Score | N1: Status | O1: Writer Assigned | P1: Draft Due Date | Q1: Notes
A2: 46062 | B2: Monday | C2: Week 1 | D2: ‘Big boy’ — weighing 525 pounds — found hiding under California home after wildfire | E2: Miami Herald | F2: 1052633 | G2: 45687 | H2: 15 | I2: OnlyFans' Annie Knight ‘Bleeding’ After Sleeping With 583 Men in 6 Hours | J2: Us Weekly | K2: 1045121 | L2: 45798 | M2: 15 | N2: Not Started
A3: 46063 | B3: Tuesday | C3: Week 1 | D3: Bill Belichick's Girlfriend Jordon Hudson Stuns in Vintage-Style Bikini | E3: Us Weekly | F3: 863790 | G3: 45829 | H3: 14 | I3: OnlyFans’ Lily Phillips Reveals How Much Money She Makes From Sex Challenges | J3: Us Weekly | K3: 855886 | L3: 45671 | M3: 14 | N3: Not Started
A4: 46064 | B4: Wednesday | C4: Week 1 | D4: Kylie Jenner and J. Lo’s Celebrity Hair Stylist Jesus Guerrero Dies | E4: Us Weekly | F4: 516992 | G4: 45711 | H4: 14 | I4: Virginia Giuffre, a crusader for Jeffrey Epstein victims, dies at 41 | J4: Miami Herald | K4: 1144867 | L4: 45772 | M4: 13 | N4: Not Started
A5: 46065 | B5: Thursday | C5: Week 1 | D5: The Rise Of The Competitive-Sex Trend. They’re sleeping with hundreds of men a day — and earning millions. Creators and experts explore the implications of turning sex stunts into a revenue stream | E5: Us Weekly | F5: 698185 | G5: 45848 | H5: 13 | I5: The Real Reason 24-Year-Old Jordon Hudson Is Dating Bill Belichick: Source | J5: Us Weekly | K5: 641930 | L5: 45779 | M5: 13 | N5: Not Started
A6: 46066 | B6: Friday | C6: Week 1 | D6: Hundreds at Alligator Alcatraz have no criminal charges or convictions, records show | E6: Miami Herald | F6: 627809 | G6: 45851 | H6: 13 | I6: Jennifer Love Hewitt Shows Off her Curves in Gorgeous Little Black Dress on Red Carpet | J6: Us Weekly | K6: 610246 | L6: 45853 | M6: 13 | N6: Not Started
A7: 46069 | B7: Monday | C7: Week 2 | D7: Cop beats Homeland Security agent in ‘parking lot rage’ at CA Costco, lawyer says | E7: Miami Herald | F7: 599532 | G7: 45846 | H7: 13 | I7: Homeowner guns down 19-year-old installing fiber optic cable, Texas cops say | J7: Miami Herald | K7: 598807 | L7: 45834 | M7: 13 | N7: Not Started
